Workbook
Name AMORTISSEMENT_EMPRUNT: IF(Values_Entered,Header_Row+Number_of_Payments,Header_Row)
Name annee: #REF!
Name Beg_Bal: #REF!
Name bp: #REF!
Name coutassurance: #REF!
Name coutinterets: #REF!
Name couttotal: #REF!
Name dureepret: #REF!
Name End_Bal: #REF!
Name Extra_Pay: #REF!
Name Header_Row: ROW(#REF!)
Name Int: #REF!
Name Interest_Rate: #REF!
Name Last_Row: IF(Values_Entered,Header_Row+Number_of_Payments,Header_Row)
Name Loan_Amount: #REF!
Name Loan_Start: #REF!
Name Loan_Years: #REF!
Name mensualiteassurance: #REF!
Name mensualitehorsassurance: #REF!
Name mensualitetotale: #REF!
Name mois: #REF!
Name Num_Pmt_Per_Year: #REF!
Name Number_of_Payments: MATCH(0.01,End_Bal,-1)+1
Name Pay_Num: #REF!
Name pret: #REF!
Name Princ: #REF!
Name Sched_Pay: #REF!
Name Scheduled_Extra_Payments: #REF!
Name Scheduled_Monthly_Payment: #REF!
Name tauxassurance: #REF!
Name tauxinteret: #REF!
Name test: #REF!
Name Total_Pay: #REF!
Name Values_Entered: IF(Loan_Amount*Interest_Rate*Loan_Years*Loan_Start>0,1,0)

Sheet Guide d'utilisation
C2: Annexe 52 (outil ) : Business plan automatisé - Guide d'utilisation
C5: Remarque : la réalisation du business plan se fait essentiellement sur l'onglet N° 2 "Données à saisir". Avant de compléter cet Onglet, il conviendrait de renseigner d'abord les onglets N° 4-5-6-7-8-9
C8: Pour modifier les cellules, un mot de passe est éxigé | I8: bp6688 | J8: DEC2024
C10: Présentation de l'outil
C11: N° | D11: Onglet | F11: Objectif et consignes d'utilisation
C13: 1 | D13: Guide d'utilisation | F13: Explications permettant d'utiliser l'outil
C18: 2 | D18: Données à saisir | F18: Les données liées au projet seront saisies dans cet onglet qui permettra de générer automatiquement l'intégralités des éléments constituant le business plan. Cet onglet récupère et exploite les données saisies dans les onglets N° 5-6-7-8 et 9. les cellules Bleues sont à renseigner
C21: 3 | D21: Plan financier à imprimer | F21: Cet onglet permet d'afficher le plan financier, l'expert-comptable vérifie la viabilité des données avant de le présenter au client
C24: 4 | D24: Amortissement des immobilisations | F24: Phase préalable à l'onglet N°2 , Il permet de calculer la durée d'amortissement des immobilisations
C29: 5 | D29: Chiffres d'affaires | F29: Cet onglet doit être renseigner avant l'onglet N° 2 , il permet de faire des simulation de chiffres d'affaires, l'expert-comptable identifie avec le client les différentes hypothèses liées au prix de vente
C30: 6 | D30: Achats consommés | F30: Cet onglet s'inscrit dans la même logique que l'onglet N°5.
C31: 7 | D31: Charges de personnel | F31: l'outil permet de déterminer les charges du personnel. L'expert-comptable doit faire attention au type de contrat, et utiliser si besoin l'outil proposé en Annexe 29 en cas de recours à un contrat de type CTA
C32: 8 | D32: Amortissement du prêt | F32: Permet de déterminer les mensualités et intérêts du prêt
C33: 9 | D33: Impots et taxes | F33: Onglet destiné au calcul de la CFE et de l'IBS
C34: 10 | D34: Van | F34: Récupère automatiquement les données de l'onglet N3 et calcule automatiquement les Cash flows, VAN et le TRI
C35: 11 | D35: Indicateurs | F35: Récupère automatiquement les données de l'onglet N3 et calcule automatiquement les rentabilité financière et économique du projet

Sheet Données à saisir
A1: Saisissez dans cet onglet toutes les données de votre projet
A2: Le plan financier apparaitra dans l'onglet suivant
A3: Le détail des charges apparait dans les onglets suivants | J3: Micro-entreprise | K3: Oui | L3: Marchandises (y compris hébergement et restauration) | N3: Impôt sur le revenu
A5: Consignes d'utilisation : Renseignez les cases en "Bleu" uniquement | J5: Entreprise individuelle au réel (IR) | K5: Non | L5: Services | N5: Impôt sur les sociétés
J6: EURL (IS) | L6: Mixte
A7: Prénom, nom : | B7: MALEK KAMEL | J7: SARL (IS)
A8: Intitulé de votre projet : | B8: E.G.J | D8: Nom du projet | J8: SAS (IS)
A9: Votre statut juridique : | B9: SARL (IS) | D9: Sélectionnez dans la liste déroulante (obligatoire) | J9: SASU (IS)
A10: Votre numéro de téléphone : | B10: 06.86.27.18.97
A11: Votre adresse e-mail : | B11: contact@egjstartp.fr
A12: Votre ville ou commune d'activité : | B12: 116 AV FONTAINBLEAU 94270 LE KREMLIN BICETRE | J12: Micro-entreprise | K12: IR
J13: Entreprise individuelle au réel (IR) | K13: IR
A14: Vente de marchandises ou de services ? | B14: Services | E14: Sélectionnez dans la liste déroulante (obligatoire) | J14: EURL (IS) | K14: IS
A15: 1) Vos besoins de démarrage : | J15: SARL (IS) | K15: IS
A16: Listez toutes les dépenses ou investissements que vous devrez faire avant même de démarrer l’activité, en hors taxes (ou TTC si vous n'êtes pas soumis à la TVA) | J16: SAS (IS) | K16: IS
B17: Montant | J17: SASU (IS) | K17: IS
A18: Frais d'établiseement | B18: 0
A19: Frais d’ouverture de compteurs | C19: Dans le cas de la société OVO X, les frais de creation et formaités sont comptabilisées en charge
A20: Logiciels, formations | C20: étant donné que la société OVO X beneficie d'une exonerations des droit d'enregistrement et autres taxes,
A21: Dépôt marque, brevet, modèle | B21: 0 | C21: nous supposons, qu'il n'y a pas de frais préliminaires
A22: Droits d’entrée
A23: Achat fonds de commerce ou parts
A24: Droit au bail
A25: Caution ou dépôt de garantie
A26: Frais de dossier
A27: Frais de notaire ou d’avocat
A28: Enseigne et éléments de communication
A29: Mobilier et matériel informatique | B29: 1300 | C29: Acquisition d'immeuble
A30: Engins eu autres materiaux de construction | B30: 100000 | C30: Pour l'aménagement du local
A31: Matériel de transport | B31: 25000 | C31: Matériel, outillage, machines, véhicules…
A32: Equipement | B32: 0 | C32: Fournitures, ordinateur, imprimante
A33: Dépot de garantie | B33: 0 | C33: Matières premières, produits finis ou semi-finis
A34: Trésorerie de départ | B34: 212500 | C34: Somme d’argent gardée en prévision du démarrage de l’activité pour financer le cycle d'exploitation
A35: TOTAL | B35: =SUM(B18:B34) -> 338800
B39: Montant à amortir | C39: Année 1 | D39: Année 2 | E39: Année 3 | F39: Année 4 | G39: Année 5 | H39: Année 6 | I39: Année 7 | J39: Année 8 | K39: Année 9 | L39: Année 10 | M39: TOTAL
B40: =SUM(B18,B20,B22,B26:B32) -> 126300 | C40: =IF(ISERROR($B40/$C$37),0,$B40/$C$37) -> 0 | D40: =IF($B40>(SUM(C40:$C40)),IF(ISERROR($B40/$C$37),"",$B40/$C$37),0) | E40: =IF($B40>(SUM($C40:D40)),IF(ISERROR($B40/$C$37),"",$B40/$C$37),0) | F40: =IF($B40>(SUM($C40:E40)),IF(ISERROR($B40/$C$37),"",$B40/$C$37),0) | G40: =IF($B40>(SUM($C40:F40)),IF(ISERROR($B40/$C$37),"",$B40/$C$37),0) | H40: =IF($B40>(SUM($C40:G40)),IF(ISERROR($B40/$C$37),"",$B40/$C$37),0) | I40: =IF($B40>(SUM($C40:H40)),IF(ISERROR($B40/$C$37),"",$B40/$C$37),0) | J40: =IF($B40>(SUM($C40:I40)),IF(ISERROR($B40/$C$37),"",$B40/$C$37),0) | K40: =IF($B40>(SUM($C40:J40)),IF(ISERROR($B40/$C$37),"",$B40/$C$37),0) | L40: =IF($B40>(SUM($C40:K40)),IF(ISERROR($B40/$C$37),"",$B40/$C$37),0) | M40: =SUM(C40:L40) -> 0
A41: =A18 -> Frais d'établiseement | B41: =B18 -> 0 | C41: =IF(ISERROR($B41/$C$37),0,$B41/$C$37) -> 0 | D41: =IF($B41>(SUM(C41:$C41)),IF(ISERROR($B41/$C$37),"",$B41/$C$37),0) -> 0 | E41: =IF($B41>(SUM($C41:D41)),IF(ISERROR($B41/$C$37),"",$B41/$C$37),0) -> 0 | F41: =IF($B41>(SUM($C41:E41)),IF(ISERROR($B41/$C$37),"",$B41/$C$37),0) -> 0 | G41: =IF($B41>(SUM($C41:F41)),IF(ISERROR($B41/$C$37),"",$B41/$C$37),0) -> 0 | H41: =IF($B41>(SUM($C41:G41)),IF(ISERROR($B41/$C$37),"",$B41/$C$37),0) -> 0 | I41: =IF($B41>(SUM($C41:H41)),IF(ISERROR($B41/$C$37),"",$B41/$C$37),0) -> 0 | J41: =IF($B41>(SUM($C41:I41)),IF(ISERROR($B41/$C$37),"",$B41/$C$37),0) -> 0 | K41: =IF($B41>(SUM($C41:J41)),IF(ISERROR($B41/$C$37),"",$B41/$C$37),0) -> 0 | L41: =IF($B41>(SUM($C41:K41)),IF(ISERROR($B41/$C$37),"",$B41/$C$37),0) -> 0 | M41: =SUM(C41:L41) -> 0
J42: =IF($B42>(SUM($C42:I42)),IF(ISERROR($B42/$C$37),"",$B42/$C$37),0) -> 0 | K42: =IF($B42>(SUM($C42:J42)),IF(ISERROR($B42/$C$37),"",$B42/$C$37),0) -> 0 | L42: =IF($B42>(SUM($C42:K42)),IF(ISERROR($B42/$C$37),"",$B42/$C$37),0) -> 0 | M42: =SUM(C42:L42) -> 0
A43: =A20 -> Logiciels, formations | B43: =B20 -> 0 | C43: =IF(ISERROR($B43/$C$37),0,$B43/$C$37) -> 0 | D43: =IF($B43>(SUM(C43:$C43)),IF(ISERROR($B43/$C$37),"",$B43/$C$37),0) -> 0 | E43: =IF($B43>(SUM($C43:D43)),IF(ISERROR($B43/$C$37),"",$B43/$C$37),0) -> 0 | F43: =IF($B43>(SUM($C43:E43)),IF(ISERROR($B43/$C$37),"",$B43/$C$37),0) -> 0 | G43: =IF($B43>(SUM($C43:F43)),IF(ISERROR($B43/$C$37),"",$B43/$C$37),0) -> 0 | H43: =IF($B43>(SUM($C43:G43)),IF(ISERROR($B43/$C$37),"",$B43/$C$37),0) -> 0 | I43: =IF($B43>(SUM($C43:H43)),IF(ISERROR($B43/$C$37),"",$B43/$C$37),0) -> 0 | J43: =IF($B43>(SUM($C43:I43)),IF(ISERROR($B43/$C$37),"",$B43/$C$37),0) -> 0 | K43: =IF($B43>(SUM($C43:J43)),IF(ISERROR($B43/$C$37),"",$B43/$C$37),0) -> 0 | L43: =IF($B43>(SUM($C43:K43)),IF(ISERROR($B43/$C$37),"",$B43/$C$37),0) -> 0 | M43: =SUM(C43:L43) -> 0
J44: =IF($B44>(SUM($C44:I44)),IF(ISERROR($B44/$C$37),"",$B44/$C$37),0) -> 0 | K44: =IF($B44>(SUM($C44:J44)),IF(ISERROR($B44/$C$37),"",$B44/$C$37),0) -> 0 | L44: =IF($B44>(SUM($C44:K44)),IF(ISERROR($B44/$C$37),"",$B44/$C$37),0) -> 0 | M44: =SUM(C44:L44) -> 0
...

Sheet Plan financier à imprimer
K2: Investissements et financements | T2: Salaires et charges sociales | AC2: Compte de résultats prévisionnel sur 5 ans | AN2: Soldes intermédiaires de gestion | BC2: Seuil de rentabilité économique | BN2: Plan de financement à cinq ans | BY2: Budget prévisionnel de trésorerie | CI2: Budget prévisionnel de trésorerie (suite)
K6: Projet : | M6: =IF(ISBLANK('Données à saisir'!$B8),"",('Données à saisir'!$B8)) -> E.G.J | T6: Projet : | V6: =IF(ISBLANK('Données à saisir'!$B8),"",('Données à saisir'!$B8)) -> E.G.J | AC6: Projet : | AE6: =IF(ISBLANK('Données à saisir'!$B8),"",('Données à saisir'!$B8)) -> E.G.J | AN6: Projet : | AP6: =IF(ISBLANK('Données à saisir'!$B8),"",('Données à saisir'!$B8)) -> E.G.J | BC6: Projet : | BE6: =IF(ISBLANK('Données à saisir'!$B8),"",('Données à saisir'!$B8)) -> E.G.J | BN6: Projet : | BP6: =IF(ISBLANK('Données à saisir'!$B8),"",('Données à saisir'!$B8)) -> E.G.J | BY6: Projet : | CA6: =IF(ISBLANK('Données à saisir'!$B8),"",('Données à saisir'!$B8)) -> E.G.J | CI6: Projet : | CK6: =IF(ISBLANK('Données à saisir'!$B8),"",('Données à saisir'!$B8)) -> E.G.J
K7: Porteur de projet : | M7: =IF(ISBLANK('Données à saisir'!$B7),"",('Données à saisir'!$B7)) -> MALEK KAMEL | T7: Porteur de projet : | V7: =IF(ISBLANK('Données à saisir'!$B7),"",('Données à saisir'!$B7)) -> MALEK KAMEL | AC7: Porteur de projet : | AE7: =IF(ISBLANK('Données à saisir'!$B7),"",('Données à saisir'!$B7)) -> MALEK KAMEL | AN7: Porteur de projet : | AP7: =IF(ISBLANK('Données à saisir'!$B7),"",('Données à saisir'!$B7)) -> MALEK KAMEL | BC7: Porteur de projet : | BE7: =IF(ISBLANK('Données à saisir'!$B7),"",('Données à saisir'!$B7)) -> MALEK KAMEL | BN7: Porteur de projet : | BP7: =IF(ISBLANK('Données à saisir'!$B7),"",('Données à saisir'!$B7)) -> MALEK KAMEL | BY7: Porteur de projet : | CA7: =IF(ISBLANK('Données à saisir'!$B7),"",('Données à saisir'!$B7)) -> MALEK KAMEL | CI7: Porteur de projet : | CK7: =IF(ISBLANK('Données à saisir'!$B7),"",('Données à saisir'!$B7)) -> MALEK KAMEL
AG8: Année 1 | AH8: Année 2 | AI8: Année 3 | AJ8: Année 4 | AK8: Année 5
K9: INVESTISSEMENTS | Q9: Montant hors taxes | U9: Statut juridique : | X9: =C33 -> SARL (IS) | BG9: Année 1 | BH9: Année 2 | BI9: Année 3 | BJ9: Année 4 | BK9: Année 5
AC10: Produits d'exploitation | AG10: =SUM(AG11:AG12) -> 1415040 | AH10: =SUM(AH11:AH12) -> 1556544 | AI10: =SUM(AI11:AI12) -> 1712198.4 | AJ10: =SUM(AJ11:AJ12) -> 1883418.2 | AK10: =SUM(AK11:AK12) -> 2071760.1
U11: Statut social du/des dirigeants : | X11: =IF(X9="sas (is)","Assimilé-salarié",IF(X9="sasu (is)","Assimilé-salarié","Travailleur non salarié")) -> Travailleur non salarié | AC11: PRESTATION DE SERVICES | AG11: ='Données à saisir'!D116 -> 1415040 | AH11: =AG11+AG11*'Données à saisir'!D118 -> 1556544 | AI11: =AH11+AH11*'Données à saisir'!D119 -> 1712198.4 | AJ11: =AI11+AI11*'Données à saisir'!D120 -> 1883418.2 | AK11: =AJ11+AJ11*'Données à saisir'!D121 -> 2071760.1 | AQ11: Année 1 | AR11: % | AS11: Année 2 | AT11: % | AU11: Année 3 | AV11: % | AW11: Année 4 | AX11: % | AY11: Année 5 | AZ11: % | BC11: Ventes + Production réelle | BG11: =AG10 -> 1415040 | BH11: =AH10 -> 1556544 | BI11: =AI10 -> 1712198.4 | BJ11: =AJ10 -> 1883418.2 | BK11: =AK10 -> 2071760.1 | BY11: Première année
K12: Immobilisations incorporelles | Q12: =SUM(Q13:Q22) -> 0 | AG12: ='Données à saisir'!I116 -> 0 | AH12: =AG12+AG12*'Données à saisir'!I118 -> 0 | AI12: =AH12+AH12*'Données à saisir'!I119 -> 0 | AJ12: =AI12+AI12*'Données à saisir'!I120 -> 0 | AK12: =AJ12+AJ12*'Données à saisir'!I121 -> 0 | BC12: Achats consommés | BG12: =AQ15 -> 78613.333 | BH12: =AS15 -> 86474.667 | BI12: =AU15 -> 95122.133 | BJ12: =AW15 -> 104634.35 | BK12: =AY15 -> 115097.78 | BR12: Année 1 | BS12: Année 2 | BT12: Année 3 | BU12: Année 4 | BV12: Année 5
K13: ='Données à saisir'!A18 -> Frais d'établiseement | Q13: =IF(ISBLANK('Données à saisir'!B18),"",'Données à saisir'!B18) -> 0 | X13: Année 1 | Y13: Année 2 | Z13: Année 3 | AC13: Charges d'exploitation | AG13: =AG14 -> 78613.333 | AH13: =AH14 -> 86474.667 | AI13: =AI14 -> 95122.133 | AJ13: =AJ14 -> 104634.35 | AK13: =AK14 -> 115097.78 | AN13: Chiffre d'affaires | AQ13: =AG10 -> 1415040 | AR13: 1 | AS13: =AH10 -> 1556544 | AT13: 1 | AU13: =AI10 -> 1712198.4 | AV13: 1 | AW13: =+AJ10 -> 1883418.2 | AX13: 1 | AY13: =+AK10 -> 2071760.1 | AZ13: 1 | BC13: Total des coûts variables | BG13: =BG12 -> 78613.333 | BH13: =BH12 -> 86474.667 | BI13: =BI12 -> 95122.133 | BJ13: =BJ12 -> 104634.35 | BK13: =BK12 -> 115097.78 | CB13: Mois 1 | CC13: Mois 2 | CD13: Mois 3 | CE13: Mois 4 | CF13: Mois 5 | CI13: Mois 6 | CJ13: Mois 7 | CK13: Mois 8 | CL13: Mois 9 | CM13: Mois 10 | CN13: Mois 11 | CO13: Mois 12 | CP13: TOTAL
B14: Etude financière prévisionnelle sur 3 ans | K14: ='Données à saisir'!A19 -> Frais d’ouverture de compteurs | Q14: =IF(ISBLANK('Données à saisir'!B19),"",'Données à saisir'!B19) | AC14: Achats consommés | AG14: ='Achats consommés '!C18 -> 78613.333 | AH14: ='Achats consommés '!D18 -> 86474.667 | AI14: ='Achats consommés '!E18 -> 95122.133 | AJ14: ='Achats consommés '!F18 -> 104634.35 | AK14: ='Achats consommés '!G18 -> 115097.78 | AN14: Ventes + production réelle | AQ14: =AG10 -> 1415040 | AR14: 1 | AS14: =AH10 -> 1556544 | AT14: 1 | AU14: =AI10 -> 1712198.4 | AV14: 1 | AW14: =+AJ10 -> 1883418.2 | AX14: 1 | AY14: =+AK10 -> 2071760.1 | AZ14: 1 | BC14: Marge sur coûts variables | BG14: =BG11-BG13 -> 1336426.7 | BH14: =BH11-BH13 -> 1470069.3 | BI14: =BI11-BI13 -> 1617076.3 | BJ14: =BJ11-BJ13 -> 1778783.9 | BK14: =BK11-BK13 -> 1956662.3 | BN14: Immobilisations | BR14: =Q12+Q23 -> 126300
K15: ='Données à saisir'!A20 -> Logiciels, formations | Q15: =IF(ISBLANK('Données à saisir'!B20),"",'Données à saisir'!B20) | T15: Rémunération du (des) dirigeants | X15: ='Données à saisir'!B137 -> 50000 | Y15: ='Données à saisir'!C137 -> 60000 | Z15: ='Données à saisir'!D137 -> 70000 | AN15: Achats consommés | AQ15: =AG14 -> 78613.333 | AR15: =AQ15/$AQ$14 -> 0.055555556 | AS15: =AH14 -> 86474.667 | AT15: =AS15/$AS$14 -> 0.055555556 | AU15: =AI14 -> 95122.133 | AV15: =AU15/$AU$14 -> 0.055555556 | AW15: =+AJ14 -> 104634.35 | AX15: =AW15/$AW$14 -> 0.055555556 | AY15: =+AK14 -> 115097.78 | AZ15: =AY15/$AY$14 -> 0.055555556 | BC15: Taux de marge sur coûts variables | BG15: =IF(ISERROR(BG14/BG11),0,BG14/BG11) -> 0.94444444 | BH15: =IF(ISERROR(BH14/BH11),0,BH14/BH11) -> 0.94444444 | BI15: =IF(ISERROR(BI14/BI11),0,BI14/BI11) -> 0.94444444 | BJ15: =IF(ISERROR(BJ14/BJ11),0,BJ14/BJ11) -> 0.94444444 | BK15: =IF(ISERROR(BK14/BK11),0,BK14/BK11) -> 0.94444444 | BN15: Acquisition des stocks | BR15: =Q30 -> 0 | BY15: Apport personnel | CB15: =BR19 -> 38800 | CP15: =SUM(CB15:CO15) -> 38800
K16: ='Données à saisir'!A21 -> Dépôt marque, brevet, modèle | Q16: =IF(ISBLANK('Données à saisir'!B21),"",'Données à saisir'!B21) -> 0 | U16: % augmentation | Y16: =IF(ISERROR((Y15-X15)/X15),"",(Y15-X15)/X15) -> 0.2 | Z16: =IF(ISERROR((Z15-Y15)/Y15),"",(Z15-Y15)/Y15) -> 0.16666667 | AC16: Marge brute | AG16: =AG10-AG13 -> 1336426.7 | AH16: =AH10-AH13 -> 1470069.3 | AI16: =AI10-AI13 -> 1617076.3 | AJ16: =AJ10-AJ13 -> 1778783.9 | AK16: =AK10-AK13 -> 1956662.3 | AN16: Marge globale | AQ16: =AQ14-AQ15 -> 1336426.7 | AR16: =AQ16/$AQ$14 -> 0.94444444 | AS16: =AS14-AS15 -> 1470069.3 | AT16: =AS16/$AS$14 -> 0.94444444 | AU16: =AU14-AU15 -> 1617076.3 | AV16: =AU16/AU14 -> 0.94444444 | AW16: =AW14-AW15 -> 1778783.9 | AX16: =AW16/AW14 -> 0.94444444 | AY16: =AY14-AY15 -> 1956662.3 | AZ16: =AY16/AY14 -> 0.94444444 | BC16: Coûts fixes | BG16: =SUM(AQ17,AQ19,AQ20,AQ22,AQ24) -> 785303.87 | BH16: =SUM(AS17,AS19,AS20,AS22,AS24) -> 877786.93 | BI16: =SUM(AU17,AU19,AU20,AU22,AU24) -> 958687.8 | BJ16: =SUM(AW17,AW19,AW20,AW22,AW24) -> #REF! | BK16: =SUM(AY17,AY19,AY20,AY22,AY24) -> #REF! | BN16: Variation du Besoin en fonds de roulement | BR16: =BG39 -> 103381.92 | BS16: =BH39-BG39 -> 10338.192 | BT16: =+BI39-BH39 -> 11372.011 | BU16: =+BJ39-BI39 -> 12509.212 | BV16: =+BK39-BJ39 -> 13760.133 | BY16: Emprunts | CB16: =BR20 -> 300000 | CP16: =SUM(CB16:CO16) -> 300000
K17: ='Données à saisir'!A22 -> Droits d’entrée | Q17: =IF(ISBLANK('Données à saisir'!B22),"",'Données à saisir'!B22) | T17: Charges sociales du (des) dirigeant(s) | X17: =X15*0.45 -> 22500 | Y17: =Y15*0.45 -> 27000 | Z17: =Z15*0.45 -> 31500 | AC17: Charges externes | AG17: =SUM(AG18:AG33) -> 393458 | AH17: =SUM(AH18:AH33) -> 431113.5 | AI17: =SUM(AI18:AI33) -> 468957.87 | AJ17: =SUM(AJ18:AJ33) -> 513429.4 | AK17: =SUM(AK18:AK33) -> 562102.17 | AN17: Charges externes | AQ17: =AG17 -> 393458 | AR17: =AQ17/$AQ$14 -> 0.27805433 | AS17: =AH17 -> 431113.5 | AT17: =AS17/AS$14 -> 0.2769684 | AU17: =AI17 -> 468957.87 | AV17: =AU17/AU$14 -> 0.27389225 | AW17: =+AJ17 -> 513429.4 | AX17: =AW17/AW$14 -> 0.27260509 | AY17: =+AK17 -> 562102.17 | AZ17: =AY17/AY$14 -> 0.27131625 | BC17: Total des charges | BG17: =BG12+BG16 -> 863917.2 | BH17: =BH12+BH16 -> 964261.6 | BI17: =BI12+BI16 -> 1053809.9 | BJ17: =BJ12+BJ16 -> #REF! | BK17: =BK12+BK16 -> #REF! | BN17: Remboursement d'emprunts | BR17: =AQ45 -> 49706.28 | BS17: =AS45 -> 49706.28 | BT17: =AU45 -> 49706.28 | BU17: =AW45 -> 49706.28 | BV17: =AY45 -> 49706.28 | BY17: Subventions | CB17: =BR21 -> 0 | CP17: =SUM(CB17:CO17) -> 0
K18: ='Données à saisir'!A23 -> Achat fonds de commerce ou parts | Q18: =IF(ISBLANK('Données à saisir'!B23),"",'Données à saisir'!B23) | AC18: ='Données à saisir'!A78 -> Assurances | AG18: =IF(ISBLANK('Données à saisir'!B78),0,'Données à saisir'!B78) -> 16380 | AH18: =IF(ISBLANK('Données à saisir'!C78),0,'Données à saisir'!C78) -> 18018 | AI18: =IF(ISBLANK('Données à saisir'!D78),0,'Données à saisir'!D78) -> 19819.8 | AJ18: =IF(ISBLANK('Données à saisir'!E78),0,'Données à saisir'!E78) -> 21801.78 | AK18: =IF(ISBLANK('Données à saisir'!F78),0,'Données à saisir'!F78) -> 23981.958 | AN18: Valeur ajoutée | AQ18: =AQ16-AQ17 -> 942968.67 | AR18: =AQ18/$AQ$14 -> 0.66639011 | AS18: =AS16-AS17 -> 1038955.8 | AT18: =AS18/AS$14 -> 0.66747605 | AU18: =AU16-AU17 -> 1148118.4 | AV18: =AU18/AU$14 -> 0.6705522 | AW18: =AW16-AW17 -> 1265354.5 | AX18: =AW18/AW$14 -> 0.67183935 | AY18: =AY16-AY17 -> 1394560.1 | AZ18: =AY18/AY$14 -> 0.6731282 | BC18: Résultat courant avant impôts | BG18: =AG44 -> 551122.8 | BH18: =AH44 -> 592282.4 | BI18: =AI44 -> 658388.46 | BJ18: =AJ44 -> #REF! | BK18: =AK44 -> #REF! | BN18: Total des besoins | BR18: =SUM(BR14:BR17) -> 279388.2 | BS18: =SUM(BS14:BS17) -> 60044.472 | BT18: =SUM(BT14:BT17) -> 61078.291 | BU18: =SUM(BU14:BU17) -> 62215.492 | BV18: =SUM(BV14:BV17) -> 63466.413 | BY18: Autres financements | CB18: =BR22 | CP18: =SUM(CB18:CO18) -> 0
K19: ='Données à saisir'!A24 -> Droit au bail | Q19: =IF(ISBLANK('Données à saisir'!B24),"",'Données à saisir'!B24) | T19: Salaires des employés | X19: ='Données à saisir'!B136 -> 222184 | Y19: ='Données à saisir'!C136 -> 255511.6 | Z19: ='Données à saisir'!D136 -> 281062.76 | AC19: ='Données à saisir'!A79 -> Abonnement (téléphone...) | AG19: =IF(ISBLANK('Données à saisir'!B79),0,'Données à saisir'!B79) -> 468 | AH19: =IF(ISBLANK('Données à saisir'!C79),0,'Données à saisir'!C79) -> 468 | AI19: =IF(ISBLANK('Données à saisir'!D79),0,'Données à saisir'!D79) -> 468 | AJ19: =IF(ISBLANK('Données à saisir'!E79),0,'Données à saisir'!E79) -> 468 | AK19: =IF(ISBLANK('Données à saisir'!F79),0,'Données à saisir'!F79) -> 468 | AN19: Impôts et taxes | AQ19: =AG36 -> 1900 | AR19: =AQ19/$AQ$14 -> 0.0013427182 | AS19: =AH36 -> 2100 | AT19: =AS19/AS$14 -> 0.0013491427 | AU19: =AI36 -> 2110 | AV19: =AU19/AU$14 -> 0.0012323338 | AW19: =+AJ36 -> 2130 | AX19: =AW19/AW$14 -> 0.0011309225 | AY19: =+AK36 -> 2150 | AZ19: =AY19/AY$14 -> 0.001037765 | BC19: Seuil de rentabilité (chiffre d'affaires) | BG19: =IF(ISERROR(BG16/BG15),0,BG16/BG15) -> 831498.22 | BH19: =IF(ISERROR(BH16/BH15),0,BH16/BH15) -> 929421.46 | BI19: =IF(ISERROR(BI16/BI15),0,BI16/BI15) -> 1015081.2 | BJ19: =IF(ISERROR(BJ16/BJ15),0,BJ16/BJ15) -> 0 | BK19: =IF(ISERROR(BK16/BK15),0,BK16/BK15) -> 0 | BN19: Apport personnel | BR19: =Q37 -> 38800 | BY19: Vente de produits finis | CB19: ='Données à saisir'!D104 -> 117920 | CC19: ='Données à saisir'!D105 -> 117920 | CD19: ='Données à saisir'!D106 -> 117920 | CE19: ='Données à saisir'!D107 -> 117920 | CF19: ='Données à saisir'!D108 -> 117920 | CI19: ='Données à saisir'!D109 -> 117920 | CJ19: ='Données à saisir'!D110 -> 117920 | CK19: ='Données à saisir'!D111 -> 117920 | CL19: ='Données à saisir'!D112 -> 117920 | CM19: ='Données à saisir'!D113 -> 117920 | CN19: ='Données à saisir'!D114 -> 117920 | CO19: ='Données à saisir'!D115 -> 117920 | CP19: =SUM(CB19:CO19) -> 1415040
K20: ='Données à saisir'!A25 -> Caution ou dépôt de garantie | Q20: =IF(ISBLANK('Données à saisir'!B25),"",'Données à saisir'!B25) | U20: % augmentation | Y20: =IF(ISERROR((Y19-X19)/X19),"",(Y19-X19)/X19) -> 0.15 | Z20: =IF(ISERROR((Z19-Y19)/Y19),"",(Z19-Y19)/Y19) -> 0.1 | AC20: ='Données à saisir'!A80 -> Location de matériel | AG20: =IF(ISBLANK('Données à saisir'!B80),0,'Données à saisir'!B80) -> 105630 | AH20: =IF(ISBLANK('Données à saisir'!C80),0,'Données à saisir'!C80) -> 116193 | AI20: =IF(ISBLANK('Données à saisir'!D80),0,'Données à saisir'!D80) -> 127812.3 | AJ20: =IF(ISBLANK('Données à saisir'!E80),0,'Données à saisir'!E80) -> 140593.53 | AK20: =IF(ISBLANK('Données à saisir'!F80),0,'Données à saisir'!F80) -> 154652.88 | AN20: Charges de personnel | AQ20: =SUM(AG37:AG40) -> 350230 | AR20: =AQ20/$AQ$14 -> 0.24750537 | AS20: =SUM(AH37:AH40) -> 406389.5 | AT20: =AS20/AS$14 -> 0.26108449 | AU20: =SUM(AI37:AI40) -> 452828.45 | AV20: =AU20/AU$14 -> 0.26447195 | AW20: =SUM(AJ37:AJ40) -> #REF! | AX20: =AW20/AW$14 -> #REF! | AY20: =SUM(AK37:AK40) -> #REF! | AZ20: =AY20/AY$14 -> #REF! | BC20: Excédent / insuffisance | BG20: =BG11-BG19 -> 583541.78 | BH20: =BH11-BH19 -> 627122.54 | BI20: =BI11-BI19 -> 697117.2 | BJ20: =BJ11-BJ19 -> 1883418.2 | BK20: =BK11-BK19 -> 2071760.1 | BN20: Emprunts | BR20: =Q40 -> 300000 | BY20: Vente de services | CB20: ='Données à saisir'!I104 -> 0 | CC20: ='Données à saisir'!I105 -> 0 | CD20: ='Données à saisir'!I106 -> 0 | CE20: ='Données à saisir'!I107 -> 0 | CF20: ='Données à saisir'!I108 -> 0 | CI20: ='Données à saisir'!I109 -> 0 | CJ20: ='Données à saisir'!I110 -> 0 | CK20: ='Données à saisir'!I111 -> 0 | CL20: ='Données à saisir'!I112 -> 0 | CM20: ='Données à saisir'!I113 -> 0 | CN20: ='Données à saisir'!I114 -> 0 | CO20: ='Données à saisir'!I115 -> 0 | CP20: =SUM(CB20:CO20) -> 0
K21: ='Données à saisir'!A26 -> Frais de dossier | Q21: =IF(ISBLANK('Données à saisir'!B26),"",'Données à saisir'!B26) | T21: Charges sociales employés | X21: =X19*0.25 -> 55546 | Y21: =Y19*0.25 -> 63877.9 | Z21: =Z19*0.25 -> 70265.69 | AC21: ='Données à saisir'!A81 -> Divers frais de mise en service | AG21: =IF(ISBLANK('Données à saisir'!B81),0,'Données à saisir'!B81) -> 2500 | AH21: =IF(ISBLANK('Données à saisir'!C81),0,'Données à saisir'!C81) -> 3000 | AI21: =IF(ISBLANK('Données à saisir'!D81),0,'Données à saisir'!D81) -> 0 | AJ21: =IF(ISBLANK('Données à saisir'!E81),0,'Données à saisir'!E81) -> 0 | AK21: =IF(ISBLANK('Données à saisir'!F81),0,'Données à saisir'!F81) -> 0 | AN21: Excédent brut d'exploitation | AQ21: =AQ18-AQ19-AQ20 -> 590838.67 | AR21: =AQ21/$AQ$14 -> 0.41754202 | AS21: =AS18-AS19-AS20 -> 630466.33 | AT21: =AS21/AS$14 -> 0.40504241 | AU21: =AU18-AU19-AU20 -> 693179.95 | AV21: =AU21/AU$14 -> 0.40484791 | AW21: =AW18-AW19-AW20 -> #REF! | AX21: =AW21/AW$14 -> #REF! | AY21: =AY18-AY19-AY20 -> #REF! | AZ21: =AY21/AY$14 -> #REF! | BC21: Point mort en chiffre d'affaires par jour ouvré | BG21: =BG19/(BG11/250) -> 146.90366 | BH21: =BH19/(BH11/250) -> 149.27645 | BI21: =BI19/(BI11/250) -> 148.21314 | BJ21: =BJ19/(BJ11/250) -> 0 | BK21: =BK19/(BK11/250) -> 0 | BN21: Subventions | BR21: =Q44+Q45 -> 0 | BY21: Chiffre d'affaires (total) | CB21: =SUM(CB19:CB20) -> 117920 | CC21: =SUM(CC19:CC20) -> 117920 | CD21: =SUM(CD19:CD20) -> 117920 | CE21: =SUM(CE19:CE20) -> 117920 | CF21: =SUM(CF19:CF20) -> 117920 | CI21: =SUM(CI19:CI20) -> 117920 | CJ21: =SUM(CJ19:CJ20) -> 117920 | CK21: =SUM(CK19:CK20) -> 117920 | CL21: =SUM(CL19:CL20) -> 117920 | CM21: =SUM(CM19:CM20) -> 117920 | CN21: =SUM(CN19:CN20) -> 117920 | CO21: =SUM(CO19:CO20) -> 117920 | CP21: =SUM(CB21:CO21) -> 1415040
K22: ='Données à saisir'!A27 -> Frais de notaire ou d’avocat | Q22: =IF(ISBLANK('Données à saisir'!B27),"",'Données à saisir'!B27) | AC22: ='Données à saisir'!A82 -> Electricité | AG22: =IF(ISBLANK('Données à saisir'!B82),0,'Données à saisir'!B82) -> 1230 | AH22: =IF(ISBLANK('Données à saisir'!C82),0,'Données à saisir'!C82) -> 1310 | AI22: =IF(ISBLANK('Données à saisir'!D82),0,'Données à saisir'!D82) -> 1340 | AJ22: =IF(ISBLANK('Données à saisir'!E82),0,'Données à saisir'!E82) -> 1350 | AK22: =IF(ISBLANK('Données à saisir'!F82),0,'Données à saisir'!F82) -> 1370 | AN22: Dotation amortissements | AQ22: =AG43 -> 25260 | AR22: =AQ22/$AQ$14 -> 0.017851085 | AS22: =AH43 -> 25260 | AT22: =AS22/AS$14 -> 0.01622826 | AU22: =AI43 -> 25260 | AV22: =AU22/AU$14 -> 0.014752963 | AW22: =AJ43 -> #REF! | AX22: =AW22/AW$14 -> #REF! | AY22: =AK43 -> #REF! | AZ22: =AY22/AY$14 -> #REF! | BN22: Autres financements | BR22: =Q46 | BY22: Immobilisations incorporelles | CB22: =Q12 -> 0 | CP22: =SUM(CB22:CO22) -> 0
C23: =IF(ISBLANK('Données à saisir'!B7),"",('Données à saisir'!B7)) -> MALEK KAMEL | K23: Immobilisations corporelles | Q23: =SUM(Q24:Q28) -> 126300 | AC23: ='Données à saisir'!A83 -> Carburant | AG23: =IF(ISBLANK('Données à saisir'!B83),0,'Données à saisir'!B83) -> 186300 | AH23: =IF(ISBLANK('Données à saisir'!C83),0,'Données à saisir'!C83) -> 204930 | AI23: =IF(ISBLANK('Données à saisir'!D83),0,'Données à saisir'!D83) -> 225423 | AJ23: =IF(ISBLANK('Données à saisir'!E83),0,'Données à saisir'!E83) -> 247965.3 | AK23: =IF(ISBLANK('Données à saisir'!F83),0,'Données à saisir'!F83) -> 272761.83 | AN23: Résultat d'exploitation | AQ23: =AQ21-AQ22 -> 565578.67 | AR23: =AQ23/$AQ$14 -> 0.39969094 | AS23: =AS21-AS22 -> 605206.33 | AT23: =AS23/AS$14 -> 0.38881415 | AU23: =AU21-AU22 -> 667919.95 | AV23: =AU23/AU$14 -> 0.39009495 | AW23: =AW21-AW22 -> #REF! | AX23: =AW23/AW$14 -> #REF! | AY23: =AY21-AY22 -> #REF! | AZ23: =AY23/AY$14 -> #REF! | BN23: Capacité d'auto-financement | BR23: =AQ44 -> 442912.1 | BS23: =AS44 -> 473781.8 | BT23: =AU44 -> 523361.35 | BU23: =AW44 -> #REF! | BV23: =AY44 -> #REF! | BY23: Immobilisations corporelles | CB23: =Q23 -> 126300 | CP23: =SUM(CB23:CO23) -> 126300
K24: ='Données à saisir'!A28 -> Enseigne et éléments de communication | Q24: =IF(ISBLANK('Données à saisir'!B28),"",'Données à saisir'!B28) | AC24: ='Données à saisir'!A84 -> Mutuelle | AG24: =IF(ISBLANK('Données à saisir'!B84),0,'Données à saisir'!B84) -> 3600 | AH24: =IF(ISBLANK('Données à saisir'!C84),0,'Données à saisir'!C84) -> 3700 | AI24: =IF(ISBLANK('Données à saisir'!D84),0,'Données à saisir'!D84) -> 3860 | AJ24: =IF(ISBLANK('Données à saisir'!E84),0,'Données à saisir'!E84) -> 3950 | AK24: =IF(ISBLANK('Données à saisir'!F84),0,'Données à saisir'!F84) -> 4080 | AN24: Charges financières | AQ24: =AG42 -> 14455.87 | AR24: =AQ24/$AQ$14 -> 0.010215874 | AS24: =AH42 -> 12923.93 | AT24: =AS24/AS$14 -> 0.0083029648 | AU24: =AI42 -> 9531.485 | AV24: =AU24/AU$14 -> 0.0055668111 | AW24: =AJ42 -> 9657.7213 | AX24: =AW24/AW$14 -> 0.0051277624 | AY24: =AK42 -> 7917.5593 | AZ24: =AY24/AY$14 -> 0.0038216584 | BN24: Total des ressources | BR24: =SUM(BR19:BR23) -> 781712.1 | BS24: =SUM(BS19:BS23) -> 473781.8 | BT24: =SUM(BT19:BT23) -> 523361.35 | BU24: =SUM(BU19:BU23) -> #REF! | BV24: =SUM(BV19:BV23) -> #REF! | BY24: Immobilisations (total) | CB24: =SUM(CB22:CB23) -> 126300 | CP24: =SUM(CB24:CO24) -> 126300
K25: ='Données à saisir'!A29 -> Mobilier et matériel informatique | Q25: =IF(ISBLANK('Données à saisir'!B29),"",'Données à saisir'!B29) -> 1300 | T25: Détail des amortissements | AC25: ='Données à saisir'!A85 -> Fournitures diverses | AG25: =IF(ISBLANK('Données à saisir'!B85),0,'Données à saisir'!B85) -> 920 | AH25: =IF(ISBLANK('Données à saisir'!C85),0,'Données à saisir'!C85) -> 950 | AI25: =IF(ISBLANK('Données à saisir'!D85),0,'Données à saisir'!D85) -> 970 | AJ25: =IF(ISBLANK('Données à saisir'!E85),0,'Données à saisir'!E85) -> 990 | AK25: =IF(ISBLANK('Données à saisir'!F85),0,'Données à saisir'!F85) -> 1030 | AN25: Résultat financier | AQ25: =AQ24*-1 -> -14455.87 | AR25: =AQ25/$AQ$14 -> -0.010215874 | AS25: =AS24*-1 -> -12923.93 | AT25: =AS25/AS$14 -> -0.0083029648 | AU25: =AU24*-1 -> -9531.485 | AV25: =AU25/AU$14 -> -0.0055668111 | AW25: =AW24*-1 -> -9657.7213 | AX25: =AW25/AW$14 -> -0.0051277624 | AY25: =AY24*-1 -> -7917.5593 | AZ25: =AY25/AY$14 -> -0.0038216584 | BN25: Variation de trésorerie | BR25: =BR24-BR18 -> 502323.9 | BS25: =BS24-BS18 -> 413737.33 | BT25: =BT24-BT18 -> 462283.06 | BU25: =BU24-BU18 -> #REF! | BV25: =BV24-BV18 -> #REF! | BY25: Acquisition stocks | CB25: =Q30 -> 0 | CP25: =SUM(CB25:CO25) -> 0
K26: ='Données à saisir'!A30 -> Engins eu autres materiaux de construction | Q26: =IF(ISBLANK('Données à saisir'!B30),"",'Données à saisir'!B30) -> 100000 | AC26: ='Données à saisir'!A86 -> Entretien matériel de transport | AG26: =IF(ISBLANK('Données à saisir'!B86),0,'Données à saisir'!B86) -> 48600 | AH26: =IF(ISBLANK('Données à saisir'!C86),0,'Données à saisir'!C86) -> 53460 | AI26: =IF(ISBLANK('Données à saisir'!D86),0,'Données à saisir'!D86) -> 58806 | AJ26: =IF(ISBLANK('Données à saisir'!E86),0,'Données à saisir'!E86) -> 64686.6 | AK26: =IF(ISBLANK('Données à saisir'!F86),0,'Données à saisir'!F86) -> 71155.26 | AN26: Résultat courant | AQ26: =AQ23+AQ25 -> 551122.8 | AR26: =AQ26/$AQ$14 -> 0.38947507 | AS26: =AS23+AS25 -> 592282.4 | AT26: =AS26/AS$14 -> 0.38051119 | AU26: =AU23+AU25 -> 658388.46 | AV26: =AU26/AU$14 -> 0.38452814 | AW26: =AW23+AW25 -> #REF! | AX26: =AW26/AW$14 -> #REF! | AY26: =AY23+AY25 -> #REF! | AZ26: =AY26/AY$14 -> #REF! | BN26: Excédent de trésorerie | BR26: =BR25 -> 502323.9 | BS26: =BR26+BS25 -> 916061.23 | BT26: =+BS26+BT25 -> 1378344.3 | BU26: =+BT26+BU25 -> #REF! | BV26: =+BU26+BV25 -> #REF! | BY26: Échéances emprunt | CB26: ='Amortissement de prêt '!H19 -> 4142.19 | CC26: =CB26 -> 4142.19 | CD26: =CC26 -> 4142.19 | CE26: =CB26 -> 4142.19 | CF26: =CC26 -> 4142.19 | CI26: =CF26 -> 4142.19 | CJ26: =CI26 -> 4142.19 | CK26: =CJ26 -> 4142.19 | CL26: =CK26 -> 4142.19 | CM26: =CL26 -> 4142.19 | CN26: =CM26 -> 4142.19 | CO26: =CN26 -> 4142.19 | CP26: =SUM(CB26:CO26) -> 49706.28
K27: ='Données à saisir'!A31 -> Matériel de transport | Q27: =IF(ISBLANK('Données à saisir'!B31),"",'Données à saisir'!B31) -> 25000 | AC27: ='Données à saisir'!A87 -> Nettoyage des locaux | AG27: =IF(ISBLANK('Données à saisir'!B87),0,'Données à saisir'!B87) -> 3230 | AH27: =IF(ISBLANK('Données à saisir'!C87),0,'Données à saisir'!C87) -> 3460 | AI27: =IF(ISBLANK('Données à saisir'!D87),0,'Données à saisir'!D87) -> 3680 | AJ27: =IF(ISBLANK('Données à saisir'!E87),0,'Données à saisir'!E87) -> 3760 | AK27: =IF(ISBLANK('Données à saisir'!F87),0,'Données à saisir'!F87) -> 3920 | AN27: Résultat de l'exercice | AQ27: =IF(ISERROR(AQ26-AG45),AQ26,(AQ26-AG45)) -> 417652.1 | AR27: =AQ27/$AQ$14 -> 0.29515215 | AS27: =IF(ISERROR(AS26-AH45),AS26,(AS26-AH45)) -> 448521.8 | AT27: =AS27/AS$14 -> 0.28815234 | AU27: =IF(ISERROR(AU26-AI45),AU26,(AU26-AI45)) -> 498101.35 | AV27: =AU27/AU$14 -> 0.29091334 | AW27: =IF(ISERROR(AW26-AJ45),AW26,(AW26-AJ45)) -> #REF! | AX27: =AW27/AW$14 -> #REF! | AY27: =IF(ISERROR(AY26-AK45),AY26,(AY26-AK45)) -> #REF! | AZ27: =AY27/AY$14 -> #REF! | BY27: Achats de marchandises | CB27: =CB19*'Données à saisir'!$D$126 -> 0 | CC27: =CC19*'Données à saisir'!$D$126 -> 0 | CD27: =CD19*'Données à saisir'!$D$126 -> 0 | CE27: =CE19*'Données à saisir'!$D$126 -> 0 | CF27: =CF19*'Données à saisir'!$D$126 -> 0 | CI27: =CI19*'Données à saisir'!$D$126 -> 0 | CJ27: =CJ19*'Données à saisir'!$D$126 -> 0 | CK27: =CK19*'Données à saisir'!$D$126 -> 0 | CL27: =CL19*'Données à saisir'!$D$126 -> 0 | CM27: =CM19*'Données à saisir'!$D$126 -> 0 | CN27: =CN19*'Données à saisir'!$D$126 -> 0 | CO27: =CO19*'Données à saisir'!$D$126 -> 0 | CP27: =SUM(CB27:CO27) -> 0
C28: =IF(ISBLANK('Données à saisir'!B8),"",('Données à saisir'!B8)) -> E.G.J | K28: ='Données à saisir'!A32 -> Equipement | Q28: =IF(ISBLANK('Données à saisir'!B32),"",'Données à saisir'!B32) -> 0 | AC28: ='Données à saisir'!A88 -> Budget publicité et communication | AG28: =IF(ISBLANK('Données à saisir'!B88),0,'Données à saisir'!B88) -> 1500 | AH28: =IF(ISBLANK('Données à saisir'!C88),0,'Données à saisir'!C88) -> 1800 | AI28: =IF(ISBLANK('Données à saisir'!D88),0,'Données à saisir'!D88) -> 2200 | AJ28: =IF(ISBLANK('Données à saisir'!E88),0,'Données à saisir'!E88) -> 2500 | AK28: =IF(ISBLANK('Données à saisir'!F88),0,'Données à saisir'!F88) -> 2500 | AN28: Capacité autofinancement | AQ28: =AQ27+AQ22 -> 442912.1 | AR28: =AQ28/$AQ$14 -> 0.31300323 | AS28: =AS27+AS22 -> 473781.8 | AT28: =AS28/AS$14 -> 0.3043806 | AU28: =AU27+AU22 -> 523361.35 | AV28: =AU28/AU$14 -> 0.3056663 | AW28: =AW27+AW22 -> #REF! | AX28: =AW28/AW$14 -> #REF! | AY28: =AY27+AY22 -> #REF! | AZ28: =AY28/AY$14 -> #REF! | BN28: Rappel trésorerie début année 1 : | BQ28: =Q31 -> 212500 | BY28: Charges externes | CB28: =$AG$17/12 -> 32788.167 | CC28: =$AG$17/12 -> 32788.167 | CD28: =$AG$17/12 -> 32788.167 | CE28: =$AG$17/12 -> 32788.167 | CF28: =$AG$17/12 -> 32788.167 | CI28: =$AG$17/12 -> 32788.167 | CJ28: =$AG$17/12 -> 32788.167 | CK28: =$AG$17/12 -> 32788.167 | CL28: =$AG$17/12 -> 32788.167 | CM28: =$AG$17/12 -> 32788.167 | CN28: =$AG$17/12 -> 32788.167 | CO28: =$AG$17/12 -> 32788.167 | CP28: =SUM(CB28:CO28) -> 393458
X29: Année 1 | Y29: Année 2 | Z29: Année 3 | AC29: ='Données à saisir'!A89 -> Loyer et charges locatives | AG29: =IF(ISBLANK('Données à saisir'!B89),0,'Données à saisir'!B89) -> 12300 | AH29: =IF(ISBLANK('Données à saisir'!C89),0,'Données à saisir'!C89) -> 12484.5 | AI29: =IF(ISBLANK('Données à saisir'!D89),0,'Données à saisir'!D89) -> 12671.767 | AJ29: =IF(ISBLANK('Données à saisir'!E89),0,'Données à saisir'!E89) -> 12861.844 | AK29: =IF(ISBLANK('Données à saisir'!F89),0,'Données à saisir'!F89) -> 13054.772 | BC29: Besoin en fonds de roulement | BY29: =AC36 -> Impôts et taxes | CB29: =$AG36/12 -> 158.33333 | CC29: =$AG36/12 -> 158.33333 | CD29: =$AG36/12 -> 158.33333 | CE29: =$AG36/12 -> 158.33333 | CF29: =$AG36/12 -> 158.33333 | CI29: =$AG36/12 -> 158.33333 | CJ29: =$AG36/12 -> 158.33333 | CK29: =$AG36/12 -> 158.33333 | CL29: =$AG36/12 -> 158.33333 | CM29: =$AG36/12 -> 158.33333 | CN29: =$AG36/12 -> 158.33333 | CO29: =$AG36/12 -> 158.33333 | CP29: =SUM(CB29:CO29) -> 1900
K30: ='Données à saisir'!A33 -> Dépot de garantie | Q30: =IF(ISBLANK('Données à saisir'!B33),"",'Données à saisir'!B33) -> 0 | AC30: ='Données à saisir'!A90 -> Honoraires Expert comptable, avocats | AG30: =IF(ISBLANK('Données à saisir'!B90),0,'Données à saisir'!B90) -> 10800 | AH30: =IF(ISBLANK('Données à saisir'!C90),0,'Données à saisir'!C90) -> 11340 | AI30: =IF(ISBLANK('Données à saisir'!D90),0,'Données à saisir'!D90) -> 11907 | AJ30: =IF(ISBLANK('Données à saisir'!E90),0,'Données à saisir'!E90) -> 12502.35 | AK30: =IF(ISBLANK('Données à saisir'!F90),0,'Données à saisir'!F90) -> 13127.468 | BY30: =AC37 -> Salaires employés | CB30: =$AG37/12 -> 18515.333 | CC30: =$AG37/12 -> 18515.333 | CD30: =$AG37/12 -> 18515.333 | CE30: =$AG37/12 -> 18515.333 | CF30: =$AG37/12 -> 18515.333 | CI30: =$AG37/12 -> 18515.333 | CJ30: =$AG37/12 -> 18515.333 | CK30: =$AG37/12 -> 18515.333 | CL30: =$AG37/12 -> 18515.333 | CM30: =$AG37/12 -> 18515.333 | CN30: =$AG37/12 -> 18515.333 | CO30: =$AG37/12 -> 18515.333 | CP30: =SUM(CB30:CO30) -> 222184
K31: ='Données à saisir'!A34 -> Trésorerie de départ | Q31: =IF(ISBLANK('Données à saisir'!B34),"",'Données à saisir'!B34) -> 212500 | T31: Amortissements incorporels | X31: =SUM(X33:X39) -> 0 | Y31: =SUM(Y33:Y39) -> 0 | Z31: =SUM(Z33:Z39) -> 0 | AC31: =IF(ISBLANK('Données à saisir'!A94),"",'Données à saisir'!A94) -> Libellé autre charge 1 | AG31: =IF(ISBLANK('Données à saisir'!B94),0,'Données à saisir'!B94) -> 0 | AH31: =IF(ISBLANK('Données à saisir'!C94),0,'Données à saisir'!C94) -> 0 | AI31: =IF(ISBLANK('Données à saisir'!D94),0,'Données à saisir'!D94) -> 0 | AJ31: =IF(ISBLANK('Données à saisir'!E94),0,'Données à saisir'!E94) -> 0 | AK31: =IF(ISBLANK('Données à saisir'!F94),0,'Données à saisir'!F94) -> 0 | BY31: =AC38 -> Charges sociales employés | CB31: =$AG38/12 -> 4628.8333 | CC31: =$AG38/12 -> 4628.8333 | CD31: =$AG38/12 -> 4628.8333 | CE31: =$AG38/12 -> 4628.8333 | CF31: =$AG38/12 -> 4628.8333 | CI31: =$AG38/12 -> 4628.8333 | CJ31: =$AG38/12 -> 4628.8333 | CK31: =$AG38/12 -> 4628.8333 | CL31: =$AG38/12 -> 4628.8333 | CM31: =$AG38/12 -> 4628.8333 | CN31: =$AG38/12 -> 4628.8333 | CO31: =$AG38/12 -> 4628.8333 | CP31: =SUM(CB31:CO31) -> 55546
O32: TOTAL BESOINS | Q32: =+SUM(Q12,Q23,Q30:Q31) -> 338800 | AC32: =IF(ISBLANK('Données à saisir'!A95),"",'Données à saisir'!A95) -> Libellé autre charge 2 | AG32: =IF(ISBLANK('Données à saisir'!B95),0,'Données à saisir'!B95) -> 0 | AH32: =IF(ISBLANK('Données à saisir'!C95),0,'Données à saisir'!C95) -> 0 | AI32: =IF(ISBLANK('Données à saisir'!D95),0,'Données à saisir'!D95) -> 0 | AJ32: =IF(ISBLANK('Données à saisir'!E95),0,'Données à saisir'!E95) -> 0 | AK32: =IF(ISBLANK('Données à saisir'!F95),0,'Données à saisir'!F95) -> 0 | BY32: =AC39 -> Prélèvement dirigeant(s) | CB32: =$AG39/12 -> 4166.6667 | CC32: =$AG39/12 -> 4166.6667 | CD32: =$AG39/12 -> 4166.6667 | CE32: =$AG39/12 -> 4166.6667 | CF32: =$AG39/12 -> 4166.6667 | CI32: =$AG39/12 -> 4166.6667 | CJ32: =$AG39/12 -> 4166.6667 | CK32: =$AG39/12 -> 4166.6667 | CL32: =$AG39/12 -> 4166.6667 | CM32: =$AG39/12 -> 4166.6667 | CN32: =$AG39/12 -> 4166.6667 | CO32: =$AG39/12 -> 4166.6667 | CP32: =SUM(CB32:CO32) -> 50000
C33: =IF(ISBLANK('Données à saisir'!B9),"",('Données à saisir'!B9)) -> SARL (IS) | T33: =K13 -> Frais d'établiseement | X33: ='Données à saisir'!C41 -> 0 | Y33: ='Données à saisir'!D41 -> 0 | Z33: ='Données à saisir'!E41 -> 0 | AC33: =IF(ISBLANK('Données à saisir'!A96),"",'Données à saisir'!A96) -> Libellé autre charge 3 | AG33: =IF(ISBLANK('Données à saisir'!B96),0,'Données à saisir'!B96) -> 0 | AH33: =IF(ISBLANK('Données à saisir'!C96),0,'Données à saisir'!C96) -> 0 | AI33: =IF(ISBLANK('Données à saisir'!D96),0,'Données à saisir'!D96) -> 0 | AJ33: =IF(ISBLANK('Données à saisir'!E96),0,'Données à saisir'!E96) -> 0 | AK33: =IF(ISBLANK('Données à saisir'!F96),0,'Données à saisir'!F96) -> 0 | BC33: Analyse clients / fournisseurs : | BY33: =AC40 -> Charges sociales dirigeant(s) | CB33: =$AG40/12 -> 1875 | CC33: =$AG40/12 -> 1875 | CD33: =$AG40/12 -> 1875 | CE33: =$AG40/12 -> 1875 | CF33: =$AG40/12 -> 1875 | CI33: =$AG40/12 -> 1875 | CJ33: =$AG40/12 -> 1875 | CK33: =$AG40/12 -> 1875 | CL33: =$AG40/12 -> 1875 | CM33: =$AG40/12 -> 1875 | CN33: =$AG40/12 -> 1875 | CO33: =$AG40/12 -> 1875 | CP33: =SUM(CB33:CO33) -> 22500
K34: FINANCEMENT DES INVESTISSEMENTS | Q34: Montant hors taxes | T34: =K15 -> Logiciels, formations | X34: ='Données à saisir'!C43 -> 0 | Y34: ='Données à saisir'!D43 -> 0 | Z34: ='Données à saisir'!E43 -> 0 | AN34: Capacité d'autofinancement | BF34: délai jours | BG34: Année 1 | BH34: Année 2 | BI34: Année 3 | BJ34: Année 4 | BK34: Année 5 | BY34: Total charges de personnel | CB34: =SUM(CB30:CB33) -> 29185.833 | CC34: =SUM(CC30:CC33) -> 29185.833 | CD34: =SUM(CD30:CD33) -> 29185.833 | CE34: =SUM(CE30:CE33) -> 29185.833 | CF34: =SUM(CF30:CF33) -> 29185.833 | CI34: =SUM(CI30:CI33) -> 29185.833 | CJ34: =SUM(CJ30:CJ33) -> 29185.833 | CK34: =SUM(CK30:CK33) -> 29185.833 | CL34: =SUM(CL30:CL33) -> 29185.833 | CM34: =SUM(CM30:CM33) -> 29185.833 | CN34: =SUM(CN30:CN33) -> 29185.833 | CO34: =SUM(CO30:CO33) -> 29185.833 | CP34: =SUM(CB34:CO34) -> 350230
T35: =K17 -> Droits d’entrée | X35: ='Données à saisir'!C45 -> 0 | Y35: ='Données à saisir'!D45 -> 0 | Z35: ='Données à saisir'!E45 -> 0 | AC35: Valeur ajoutée | AG35: =AG16-AG17 -> 942968.67 | AH35: =AH16-AH17 -> 1038955.8 | AI35: =AI16-AI17 -> 1148118.4 | AJ35: =AJ16-AJ17 -> 1265354.5 | AK35: =AK16-AK17 -> 1394560.1 | BC35: Besoins | BY35: =AC42 -> Frais bancaires, charges financières | CB35: =$AG42/12 -> 1204.6558 | CC35: =$AG42/12 -> 1204.6558 | CD35: =$AG42/12 -> 1204.6558 | CE35: =$AG42/12 -> 1204.6558 | CF35: =$AG42/12 -> 1204.6558 | CI35: =$AG42/12 -> 1204.6558 | CJ35: =$AG42/12 -> 1204.6558 | CK35: =$AG42/12 -> 1204.6558 | CL35: =$AG42/12 -> 1204.6558 | CM35: =$AG42/12 -> 1204.6558 | CN35: =$AG42/12 -> 1204.6558 | CO35: =$AG42/12 -> 1204.6558 | CP35: =SUM(CB35:CO35) -> 14455.87
T36: =K21 -> Frais de dossier | X36: ='Données à saisir'!C49 -> 0 | Y36: ='Données à saisir'!D49 -> 0 | Z36: ='Données à saisir'!E49 -> 0 | AC36: Impôts et taxes | AG36: =IF(ISBLANK('Données à saisir'!B92),0,'Données à saisir'!B92) -> 1900 | AH36: =IF(ISBLANK('Données à saisir'!C92),0,'Données à saisir'!C92) -> 2100 | AI36: =IF(ISBLANK('Données à saisir'!D92),0,'Données à saisir'!D92) -> 2110 | AJ36: =IF(ISBLANK('Données à saisir'!E92),0,'Données à saisir'!E92) -> 2130 | AK36: =IF(ISBLANK('Données à saisir'!F92),0,'Données à saisir'!F92) -> 2150 | BC36: Volume crédit client HT | BF36: ='Données à saisir'!D130 -> 30 | BG36: =BG11/365*$BF36 -> 116304.66 | BH36: =BH11/365*$BF36 -> 127935.12 | BI36: =BI11/365*$BF36 -> 140728.64 | BJ36: =BJ11/365*$BF36 -> 154801.5 | BK36: =BK11/365*$BF36 -> 170281.65 | BY36: Total des décaissements | CB36: =SUM(CB24:CB29,CB34:CB35) -> 193779.18 | CC36: =SUM(CC24:CC29,CC34:CC35) -> 67479.179 | CD36: =SUM(CD24:CD29,CD34:CD35) -> 67479.179 | CE36: =SUM(CE24:CE29,CE34:CE35) -> 67479.179 | CF36: =SUM(CF24:CF29,CF34:CF35) -> 67479.179 | CI36: =SUM(CI24:CI29,CI34:CI35) -> 67479.179 | CJ36: =SUM(CJ24:CJ29,CJ34:CJ35) -> 67479.179 | CK36: =SUM(CK24:CK29,CK34:CK35) -> 67479.179 | CL36: =SUM(CL24:CL29,CL34:CL35) -> 67479.179 | CM36: =SUM(CM24:CM29,CM34:CM35) -> 67479.179 | CN36: =SUM(CN24:CN29,CN34:CN35) -> 67479.179 | CO36: =SUM(CO24:CO29,CO34:CO35) -> 67479.179 | CP36: =SUM(CB36:CO36) -> 936050.15
K37: Apport personnel | Q37: =SUM(Q38:Q39) -> 38800 | T37: =K22 -> Frais de notaire ou d’avocat | X37: ='Données à saisir'!C50 -> 0 | Y37: ='Données à saisir'!D50 -> 0 | Z37: ='Données à saisir'!E50 -> 0 | AC37: Salaires employés | AG37: ='Données à saisir'!B136 -> 222184 | AH37: ='Données à saisir'!C136 -> 255511.6 | AI37: ='Données à saisir'!D136 -> 281062.76 | AJ37: ='Données à saisir'!E136 -> 309169.04 | AK37: ='Données à saisir'!F136 -> 340085.94 | BC37: Ressources | BY37: Total des encaissements | CB37: =SUM(CB15:CB20) -> 456720 | CC37: =SUM(CC15:CC20) -> 117920 | CD37: =SUM(CD15:CD20) -> 117920 | CE37: =SUM(CE15:CE20) -> 117920 | CF37: =SUM(CF15:CF20) -> 117920 | CI37: =SUM(CI15:CI20) -> 117920 | CJ37: =SUM(CJ15:CJ20) -> 117920 | CK37: =SUM(CK15:CK20) -> 117920 | CL37: =SUM(CL15:CL20) -> 117920 | CM37: =SUM(CM15:CM20) -> 117920 | CN37: =SUM(CN15:CN20) -> 117920 | CO37: =SUM(CO15:CO20) -> 117920 | CP37: =SUM(CB37:CO37) -> 1753840
K38: ='Données à saisir'!A60 -> Apport personnel ou familial | Q38: =IF(ISBLANK('Données à saisir'!B60),0,'Données à saisir'!B60) -> 38800 | AC38: Charges sociales employés | AG38: =X21 -> 55546 | AH38: =Y21 -> 63877.9 | AI38: =Z21 -> 70265.69 | AJ38: =#REF! -> #REF! | AK38: =#REF! -> #REF! | BC38: Volume dettes fournisseurs HT | BF38: ='Données à saisir'!D131 -> 60 | BG38: =BG12/365*$BF38 -> 12922.74 | BH38: =BH12/365*$BF38 -> 14215.014 | BI38: =BI12/365*$BF38 -> 15636.515 | BJ38: =BJ12/365*$BF38 -> 17200.167 | BK38: =BK12/365*$BF38 -> 18920.183 | BY38: Solde précédent | CB38: 0 | CC38: =CB40 -> 262940.82 | CD38: =CC40 -> 313381.64 | CE38: =CD40 -> 363822.46 | CF38: =CE40 -> 414263.28 | CI38: =CF40 -> 464704.1 | CJ38: =CI40 -> 515144.92 | CK38: =CJ40 -> 565585.75 | CL38: =CK40 -> 616026.57 | CM38: =CL40 -> 666467.39 | CN38: =CM40 -> 716908.21 | CO38: =CN40 -> 767349.03
K39: ='Données à saisir'!A61 -> Apports en nature (en valeur) | Q39: =IF(ISBLANK('Données à saisir'!B61),0,'Données à saisir'!B61) -> 0 | AC39: Prélèvement dirigeant(s) | AG39: ='Données à saisir'!B137 -> 50000 | AH39: ='Données à saisir'!C137 -> 60000 | AI39: ='Données à saisir'!D137 -> 70000 | AJ39: ='Données à saisir'!E137 -> 85000 | AK39: ='Données à saisir'!F137 -> 90000 | BC39: Besoin en fonds de roulement | BG39: =BG36-BG38 -> 103381.92 | BH39: =BH36-BH38 -> 113720.11 | BI39: =BI36-BI38 -> 125092.12 | BJ39: =BJ36-BJ38 -> 137601.33 | BK39: =BK36-BK38 -> 151361.47 | BY39: Solde du mois | CB39: =CB37-CB36 -> 262940.82 | CC39: =CC37-CC36 -> 50440.821 | CD39: =CD37-CD36 -> 50440.821 | CE39: =CE37-CE36 -> 50440.821 | CF39: =CF37-CF36 -> 50440.821 | CI39: =CI37-CI36 -> 50440.821 | CJ39: =CJ37-CJ36 -> 50440.821 | CK39: =CK37-CK36 -> 50440.821 | CL39: =CL37-CL36 -> 50440.821 | CM39: =CM37-CM36 -> 50440.821 | CN39: =CN37-CN36 -> 50440.821 | CO39: =CO37-CO36 -> 50440.821
K40: Emprunt | N40: taux | O40: durée mois | Q40: =SUM(Q41:Q43) -> 300000 | T40: Amortissements corporels | X40: =SUM(X42:X46) -> 25260 | Y40: =SUM(Y42:Y46) -> 25260 | Z40: =SUM(Z42:Z46) -> 25260 | AC40: Charges sociales dirigeant(s) | AG40: =X17 -> 22500 | AH40: =Y17 -> 27000 | AI40: =Z17 -> 31500 | AJ40: =#REF! -> #REF! | AK40: =#REF! -> #REF! | AQ40: Année 1 | AS40: Année 2 | AU40: Année 3 | AW40: Année 4 | AY40: Année 5 | BY40: Solde de trésorerie (cumul) | CB40: =CB39 -> 262940.82 | CC40: =CC38+CC39 -> 313381.64 | CD40: =CD38+CD39 -> 363822.46 | CE40: =CE38+CE39 -> 414263.28 | CF40: =CF38+CF39 -> 464704.1 | CI40: =CI38+CI39 -> 515144.92 | CJ40: =CJ38+CJ39 -> 565585.75 | CK40: =CK38+CK39 -> 616026.57 | CL40: =CL38+CL39 -> 666467.39 | CM40: =CM38+CM39 -> 716908.21 | CN40: =CN38+CN39 -> 767349.03 | CO40: =CO38+CO39 -> 817789.85
K41: =IF(ISBLANK('Données à saisir'!A62),"",'Données à saisir'!A62) -> Prêt n°1 (SOCIETE GENERALE) | N41: =IF(ISBLANK('Données à saisir'!C62),"",'Données à saisir'!C62) -> 0.034 | O41: =IF(ISBLANK('Données à saisir'!D62),"",'Données à saisir'!D62) -> 7 | Q41: =IF(ISBLANK('Données à saisir'!B62),0,'Données à saisir'!B62) -> 150000 | AC41: Excédent brut d'exploitation | AG41: =AG35-SUM(AG36:AG40) -> 590838.67 | AH41: =AH35-SUM(AH36:AH40) -> 630466.33 | AI41: =AI35-SUM(AI36:AI40) -> 693179.95 | AJ41: =AJ35-SUM(AJ36:AJ40) -> #REF! | AK41: =AK35-SUM(AK36:AK40) -> #REF! | CB41: =IF(CB40<0,CB40,"") | CC41: =IF(CC40<0,CC40,"") | CD41: =IF(CD40<0,CD40,"") | CE41: =IF(CE40<0,CE40,"") | CF41: =IF(CF40<0,CF40,"") | CG41: =IF(CG40<0,CG40,"") | CH41: =IF(CH40<0,CH40,"") | CI41: =IF(CI40<0,CI40,"") | ... CO41: =IF(CO40<0,CO40,"") | CP41: =SUM(CB41:CO41) -> 0
C42: =IF(ISBLANK('Données à saisir'!B10),"",('Données à saisir'!B10)) -> 06.86.27.18.97 | K42: =IF(ISBLANK('Données à saisir'!A63),"",'Données à saisir'!A63) -> Prêt n°2 (SOCIETE GENERALE) | N42: =IF(ISBLANK('Données à saisir'!C63),"",'Données à saisir'!C63) -> 0.034 | O42: =IF(ISBLANK('Données à saisir'!D63),"",'Données à saisir'!D63) -> 7 | Q42: =IF(ISBLANK('Données à saisir'!B63),0,'Données à saisir'!B63) -> 150000 | T42: =K24 -> Enseigne et éléments de communication | X42: ='Données à saisir'!C51 -> 0 | Y42: ='Données à saisir'!D51 -> 0 | Z42: ='Données à saisir'!E51 -> 0 | AC42: Frais bancaires, charges financières | AG42: ='Données à saisir'!B91+'Amortissement de prêt '!J30 -> 14455.87 | AH42: ='Données à saisir'!C91+'Amortissement de prêt '!J42 -> 12923.93 | AI42: ='Données à saisir'!D91+'Amortissement de prêt '!J66 -> 9531.485 | AJ42: ='Données à saisir'!E91+'Amortissement de prêt '!J66 -> 9657.7213 | AK42: ='Données à saisir'!F91+'Amortissement de prêt '!J78 -> 7917.5593 | AN42: Résultat de l'exercice | AQ42: =AQ27 -> 417652.1 | AS42: =AS27 -> 448521.8 | AU42: =AU27 -> 498101.35 | AW42: =AW27 -> #REF! | AY42: =AY27 -> #REF!
C43: =IF(ISBLANK('Données à saisir'!B11),"",('Données à saisir'!B11)) -> contact@egjstartp.fr | K43: =IF(ISBLANK('Données à saisir'!A64),"",'Données à saisir'!A64) -> Prêt n°3 (nom de la banque) | N43: =IF(ISBLANK('Données à saisir'!C64),"",'Données à saisir'!C64) | O43: =IF(ISBLANK('Données à saisir'!D64),"",'Données à saisir'!D64) | Q43: =IF(ISBLANK('Données à saisir'!B64),0,'Données à saisir'!B64) -> 0 | T43: =K25 -> Mobilier et matériel informatique | X43: ='Amortissement des immos'!G14 -> 260 | Y43: =X43 -> 260 | Z43: =X43 -> 260 | AC43: Dotations aux amortissements | AG43: =X48 -> 25260 | AH43: =Y48 -> 25260 | AI43: =Z48 -> 25260 | AJ43: =#REF! -> #REF! | AK43: =#REF! -> #REF! | AN43: + Dotation amortissements | AQ43: =AQ22 -> 25260 | AS43: =AS22 -> 25260 | AU43: =AU22 -> 25260 | AW43: =AW22 -> #REF! | AY43: =AY22 -> #REF!
C44: =IF(ISBLANK('Données à saisir'!B12),"",('Données à saisir'!B12)) -> 116 AV FONTAINBLEAU 94270 LE KREMLIN BICETRE | K44: =IF(ISBLANK('Données à saisir'!A65),"",'Données à saisir'!A65) -> Subvention n°1 (libellé) | Q44: =IF(ISBLANK('Données à saisir'!B65),0,'Données à saisir'!B65) -> 0 | T44: =K26 -> Engins eu autres materiaux de construction | X44: ='Données à saisir'!C53 -> 0 | Y44: ='Données à saisir'!D53 | Z44: ='Données à saisir'!E53 | AC44: Résultat avant impôts | AG44: =AG41-AG42-AG43 -> 551122.8 | AH44: =AH41-AH42-AH43 -> 592282.4 | AI44: =AI41-AI42-AI43 -> 658388.46 | AJ44: =AJ41-AJ42-AJ43 -> #REF! | AK44: =AK41-AK42-AK43 -> #REF! | AN44: Capacité d'autofinancement | AQ44: =AQ42+AQ43 -> 442912.1 | AS44: =AS42+AS43 -> 473781.8 | AU44: =AU42+AU43 -> 523361.35 | AW44: =AW42+AW43 -> #REF! | AY44: =AY42+AY43 -> #REF! | BY44: Ce tableau ne pas en compte les flux de TVA ni le besoin en fonds de roulement.
...

Sheet Amortissement des immos
B3: Outil de calcul de la durée des Amortissements
B6: Consigne d'utilisation :
B7: Compléter uniquement les cellules en "Violet"
B9: Commentaires : Recenser les immobilisations liées au projet et définir la durée d'amortissement de chaque immobilisation, puis remplir le tableau ci-dessous
B12: N° | C12: Immobilisations | D12: Valeur d'origine | E12: Durée | F12: Taux d'amortissement | G12: Amortissement annuel
B14: 1 | C14: Construction | D14: ='Données à saisir'!B29 -> 1300 | E14: 5 | F14: 0.05 | G14: =D14/E14 -> 260
B16: 2 | C16: TRAVAUX | D16: ='Données à saisir'!B30 -> 100000 | E16: 5 | F16: 0.1 | G16: =D16/E16 -> 20000
B18: 3 | C18: MATERIEL DE TRANSPORT | D18: ='Données à saisir'!B31 -> 25000 | E18: 5 | F18: 0.2 | G18: =D18/E18 -> 5000
C20: Total des immobilisations | D20: =SUM(D14:D19) -> 126300 | F20: =SUM(G14:G19) -> 25260

Sheet Chiffres d'affaires 
B2: Outil de détermination du chiffre d'affaires
B5: Consigne d'utilisation : Compléter uniquement les cellules en "Violet"
B8: Commentaires : Il convient de définir le prix de vente moyen, et déterminer la quantité vendue par année. L'objectif est de permettre à l'expert-comptable d'adapter son prévisionnel en fonction des fluctuations du marché
B11: Chiffre d'affaires
B12: Prix de vente moyen | C12: 10.33
B13: Quantité d'œufs par litre | C13: 20
B14: Prix de vente au litre | C14: =C12*C13 -> 206.6
B17: Années | C17: AN 1 | D17: AN 2 | E17: AN3 | F17: AN 4 | G17: AN 5
B18: Quantité vendues /k litres | C18: 330 | D18: 462 | E18: 660 | F18: 725.82 | G18: 803.25
B19: Chiffre d'affaires en k DA | C19: =C14*C18 -> 68178 | D19: =D18*C14 -> 95449.2 | E19: =C14*E18 -> 136356 | F19: =C14*F18 -> 149954.41 | G19: =C14*G18 -> 165951.45

Sheet Achats consommés 
B1: Outil de détermination des achats consommés
B3: Consigne d'utilisation : Compléter uniquement les cellules en "Violet"
B6: Commentaires : Il convient de définir le prix de revient moyen en tenant compte du taux de marge de production, et déterminer la quantité vendue par année. L'objectif est de permettre à l'expert-comptable d'adapter son prévisionnel en fonction des prix de l'oeuf sur le marché
B9: Achats consommés
B10: prix de revient au litre | C10: 8.32
B11: quantite d'oeufs/litre | C11: 20
B12: Achats consommés/litre | C12: =C10*C11 -> 166.4
B16: Années | C16: AN 1 | D16: AN 2 | E16: AN3 | F16: AN 4 | G16: AN 5
B17: Quantités nécéssaires à la vente | C17: 330 | D17: 462 | E17: 660 | F17: 726 | G17: 798.6
B18: Achats consommés en kDA | C18: ='Plan financier à imprimer'!AG11/18 -> 78613.333 | D18: ='Plan financier à imprimer'!AH11/18 -> 86474.667 | E18: ='Plan financier à imprimer'!AI11/18 -> 95122.133 | F18: ='Plan financier à imprimer'!AJ11/18 -> 104634.35 | G18: ='Plan financier à imprimer'!AK11/18 -> 115097.78

Sheet Charges de personnel 
B1: Outil de détermination des charges de personnel
B4: Consigne d'utilisation : Compléter uniquement les cellules en "Violet" - En cas de recours au contrat aidé (CTA) , il conviendrait d'utiliser l'outil proposé en annexe 19 pour déterminer son coût
B8: Commentaires : Le taux d'évolution des salaires est justifié par l'augmentation du volume de production pour atteindre 100% de capacité de production. L'objectif est de permettre à l'expert-comptable de justifier le coût de la masse salariale/
B12: Taux d'évolution des salaires | F12: 0.1
B14: charges de personnel
B15: Catégories | C15: Effectif | D15: Type de contrat | E15: Salaire brut estimé | F15: Salaire brut versé | G15: N | H15: N+1 | I15: N+2 | J15: N+3 | K15: N+4
B16: Directeur | C16: 1 | D16: CDI | E16: 480 | F16: 480 | G16: =F16 -> 480
B17: Gestionnaire des stocks | C17: 1 | D17: CDI | E17: 340 | F17: 340 | G17: =F17 -> 340
B18: Agent commercial | C18: 1 | D18: CDI | E18: 324 | F18: 324 | G18: 324
B19: Agent commercial | C19: 1 | D19: Aidé (CTA) | E19: 324 | F19: 150 | G19: =F19 -> 150
B20: Stagiaire | C20: 1 | D20: Stage | E20: 174 | F20: 174 | G20: 174
B21: Opérateur sur machines | C21: 2 | D21: CDI | E21: 324 | F21: 324 | G21: =C21*E21 -> 648
B22: Chauffeur livreur | C22: 1 | D22: CDD | E22: 362.4 | F22: 362.4 | G22: =C22*E22 -> 362.4
B23: Agent de sécurité | C23: 1 | D23: CDI | E23: 310.4 | F23: 310.4 | G23: =C23*E23 -> 310.4
B24: Total des salaires hors chargers | C24: 8 | E24: =1300*12 -> 15600 | F24: =D24*1.5 -> 0 | G24: 222184 | H24: =G24*1.15 -> 255511.6 | I24: =H24*1.1 -> 281062.76 | J24: =I24*1.1 -> 309169.04 | K24: =J24*1.1 -> 340085.94
B25: Charges sociales | C25: 8 | G25: =G24*0.38 -> 84429.92 | H25: =H24*0.38 -> 97094.408 | I25: =I24*0.38 -> 106803.85 | J25: =J24*0.38 -> 117484.23 | K25: =K24*0.38 -> 129232.66
B26: Total masse salariales | C26: 8 | G26: =G24+G25 -> 306613.92 | H26: =H24+H25 -> 352606.01 | I26: =I24+I25 -> 387866.61 | J26: =J24+J25 -> 426653.27 | K26: =K24+K25 -> 469318.6

Sheet Amortissement de prêt 
B1: Tableau d'amortissement du prêt
B4: Consigne d'utilisation :
B5: Compléter uniquement les cellules en "Violet"
B7: Commentaires : Déterminer le montant de prêt, fixer la durée du prêt et le taux d'intérêt applicable
C11: Montant du prêt | D11: 19900 | G11: Synthèse des éléments fournis :
C12: Taux d'intérêt annuel | D12: 0.025 | H12: Mensualité | I12: 258.23
C13: Durée du prêt en années | D13: 7 | H13: Nombre de mensualités prévues | I13: 72
C14: Nombre de versements par an | D14: 12 | H14: annuité | I14: 3098.81
C15: Date de début de l'emprunt | D15: 44562
B18: Échéance | C18: Montant mensualité | D18: Dont capital | E18: Dont intérêts | F18: Reste à rembourser (capital) | G18: Montant assurance | H18: Total échéance | I18: remboursement annuel | J18: onterets
B19: 1 | C19: 258.23418 | D19: 217.24344 | E19: 40.990742 | F19: 19682.757 | G19: 0 | H19: 4142.19 | K19: 1 | L19: 478.33 | M19: 1 441,75 € | N19: 138 558,00 € | O19: 0 | P19: 1 920,08 €
B20: 2 | C20: 258.23418 | D20: 217.69092 | E20: 40.543256 | F20: 19465.066 | G20: 0 | H20: 1251.01 | K20: 2 | L20: 473.4 | M20: 1 446,67 € | N20: 137 112,00 € | O20: 0 | P20: 1 920,08 €
B21: 3 | C21: 258.23418 | D21: 218.13933 | E21: 40.094848 | F21: 19246.926 | G21: 0 | H21: 1251.01 | K21: 3 | L21: 468.46 | M21: 1 451,61 € | N21: 135 660,00 € | O21: 0 | P21: 1 920,08 €
B22: 4 | C22: 258.23418 | D22: 218.58866 | E22: 39.645517 | F22: 19028.338 | G22: 0 | H22: 1251.01 | K22: 4 | L22: 463.5 | M22: 1 456,57 € | N22: 134 203,00 € | O22: 0 | P22: 1 920,08 €
B23: 5 | C23: 258.23418 | D23: 219.03892 | E23: 39.19526 | F23: 18809.299 | G23: 0 | H23: 1251.01 | K23: 5 | L23: 458.52 | M23: 1 461,55 € | N23: 132 742,00 € | O23: 0 | P23: 1 920,08 €
B24: 6 | C24: 258.23418 | D24: 219.4901 | E24: 38.744076 | F24: 18589.809 | G24: 0 | H24: 1251.01 | K24: 6 | L24: 453.53 | M24: 1 466,54 € | N24: 131 275,00 € | O24: 0 | P24: 1 920,08 €
B25: 7 | C25: 258.23418 | D25: 219.94222 | E25: 38.291962 | F25: 18369.866 | G25: 0 | H25: 1251.01 | K25: 7 | L25: 448.52 | M25: 1 471,56 € | N25: 129 804,00 € | O25: 0 | P25: 1 920,08 €
B26: 8 | C26: 258.23418 | D26: 220.39526 | E26: 37.838917 | F26: 18149.471 | G26: 0 | H26: 1251.01 | K26: 8 | L26: 443.49 | M26: 1 476,58 € | N26: 128 327,00 € | O26: 0 | P26: 1 920,08 €
B27: 9 | C27: 258.23418 | D27: 220.84924 | E27: 37.384939 | F27: 17928.622 | G27: 0 | H27: 1251.01 | K27: 9 | L27: 438.45 | M27: 1 481,63 € | N27: 126 845,00 € | O27: 0 | P27: 1 920,08 €
B28: 10 | C28: 258.23418 | D28: 221.30415 | E28: 36.930026 | F28: 17707.318 | G28: 0 | H28: 1251.01 | K28: 10 | L28: 433.38 | M28: 1 486,69 € | N28: 125 359,00 € | O28: 0 | P28: 1 920,08 €
B29: 11 | C29: 258.23418 | D29: 221.76 | E29: 36.474175 | F29: 17485.558 | G29: 0 | H29: 1251.01 | K29: 11 | L29: 428.3 | M29: 1 491,77 € | N29: 123 867,00 € | O29: 0 | P29: 1 920,08 € | Q29: =SUM(P19:P29) -> 0
A30: annee 1 | B30: 12 | C30: 258.23418 | D30: 222.21679 | E30: 36.017386 | F30: 17263.341 | G30: 0 | H30: 1251.01 | I30: 49706.28 | J30: 12165.87 | K30: 12 | L30: 423.21 | M30: 1 496,87 € | N30: 122 370,00 € | O30: 0 | P30: 1 920,08 €
B31: 13 | C31: 258.23418 | D31: 222.67452 | E31: 35.559656 | F31: 17040.666 | G31: 0 | H31: 258.23418 | K31: 13 | L31: 418.09 | M31: 1 501,98 € | N31: 120 868,00 € | O31: 0 | P31: 1 920,08 €
B32: 14 | C32: 258.23418 | D32: 223.1332 | E32: 35.100983 | F32: 16817.533 | G32: 0 | H32: 258.23418 | K32: 14 | L32: 412.96 | M32: 1 507,11 € | N32: 119 361,00 € | O32: 0 | P32: 1 920,08 €
B33: 15 | C33: 258.23418 | D33: 223.59281 | E33: 34.641365 | F33: 16593.94 | G33: 0 | H33: 258.23418 | K33: 15 | L33: 407.81 | M33: 1 512,26 € | N33: 117 849,00 € | O33: 0 | P33: 1 920,08 €
B34: 16 | C34: 258.23418 | D34: 224.05338 | E34: 34.1808 | F34: 16369.887 | G34: 0 | H34: 258.23418 | K34: 16 | L34: 402.64 | M34: 1 517,43 € | N34: 116 331,00 € | O34: 0 | P34: 1 920,08 €
B35: 17 | C35: 258.23418 | D35: 224.51489 | E35: 33.719287 | F35: 16145.372 | G35: 0 | H35: 258.23418 | K35: 17 | L35: 397.46 | M35: 1 522,61 € | N35: 114 809,00 € | O35: 0 | P35: 1 920,08 €
B36: 18 | C36: 258.23418 | D36: 224.97736 | E36: 33.256823 | F36: 15920.395 | G36: 0 | H36: 258.23418 | K36: 18 | L36: 392.26 | M36: 1 527,82 € | N36: 113 281,00 € | O36: 0 | P36: 1 920,08 €
B37: 19 | C37: 258.23418 | D37: 225.44077 | E37: 32.793407 | F37: 15694.954 | G37: 0 | H37: 258.23418 | K37: 19 | L37: 387.04 | M37: 1 533,04 € | N37: 111 748,00 € | O37: 0 | P37: 1 920,08 €
